{
  "cells": [
    {
      "cell_type": "markdown",
      "metadata": {
        "id": "view-in-github",
        "colab_type": "text"
      },
      "source": [
        "<a href=\"https://colab.research.google.com/github/CharlesMAdjei/m2m/blob/main/Untitled0.ipynb\" target=\"_parent\"><img src=\"https://colab.research.google.com/assets/colab-badge.svg\" alt=\"Open In Colab\"/></a>"
      ]
    },
    {
      "cell_type": "code",
      "execution_count": null,
      "metadata": {
        "id": "9jz2GzaPnyHQ"
      },
      "outputs": [],
      "source": [
        "import pandas as pd\n",
        "import numpy as np"
      ]
    },
    {
      "cell_type": "code",
      "execution_count": null,
      "metadata": {
        "colab": {
          "base_uri": "https://localhost:8080/"
        },
        "id": "Hp-1bh38lDKu",
        "outputId": "27673145-372c-4701-83ba-bdd5913220a2"
      },
      "outputs": [
        {
          "name": "stdout",
          "output_type": "stream",
          "text": [
            "Mounted at /content/gdrive/\n"
          ]
        }
      ],
      "source": [
        "from google.colab import drive\n",
        "drive.mount('/content/gdrive/', force_remount=True)"
      ]
    },
    {
      "cell_type": "code",
      "execution_count": null,
      "metadata": {
        "id": "fGjz-KBZmLGq"
      },
      "outputs": [],
      "source": [
        "path = \"/content/drive/MyDrive/m2m/VMMP\""
      ]
    },
    {
      "cell_type": "code",
      "execution_count": null,
      "metadata": {
        "colab": {
          "base_uri": "https://localhost:8080/"
        },
        "id": "_IEl1M5KmyJ6",
        "outputId": "06800569-3caa-4a70-9b3e-c8f9b7f70f0a"
      },
      "outputs": [
        {
          "name": "stdout",
          "output_type": "stream",
          "text": [
            "shell-init: error retrieving current directory: getcwd: cannot access parent directories: Transport endpoint is not connected\n",
            "pwd: error retrieving current directory: getcwd: cannot access parent directories: Transport endpoint is not connected\n"
          ]
        }
      ],
      "source": []
    },
    {
      "cell_type": "code",
      "execution_count": null,
      "metadata": {
        "colab": {
          "base_uri": "https://localhost:8080/"
        },
        "id": "_D0wY5WKnRFU",
        "outputId": "6c024444-f1c5-4987-f977-c0b3f53411a0"
      },
      "outputs": [
        {
          "name": "stdout",
          "output_type": "stream",
          "text": [
            "shell-init: error retrieving current directory: getcwd: cannot access parent directories: Transport endpoint is not connected\n",
            "ls: cannot open directory '.': Transport endpoint is not connected\n"
          ]
        }
      ],
      "source": [
        "ls"
      ]
    },
    {
      "cell_type": "code",
      "execution_count": null,
      "metadata": {
        "id": "NaC_1-YGh1mY"
      },
      "outputs": [],
      "source": []
    },
    {
      "cell_type": "code",
      "execution_count": null,
      "metadata": {
        "id": "z5o4hxWeiTVm"
      },
      "outputs": [],
      "source": []
    },
    {
      "cell_type": "code",
      "execution_count": null,
      "metadata": {
        "colab": {
          "background_save": true,
          "base_uri": "https://localhost:8080/",
          "height": 687
        },
        "id": "D5bUVDzviWId",
        "outputId": "4c4b3c71-47d3-4da1-f24f-a69b13d44f1c"
      },
      "outputs": [
        {
          "name": "stderr",
          "output_type": "stream",
          "text": [
            "ERROR:root:Internal Python error in the inspect module.\n",
            "Below is the traceback from this internal error.\n",
            "\n",
            "ERROR:root:Internal Python error in the inspect module.\n",
            "Below is the traceback from this internal error.\n",
            "\n",
            "ERROR:root:Internal Python error in the inspect module.\n",
            "Below is the traceback from this internal error.\n",
            "\n"
          ]
        },
        {
          "name": "stdout",
          "output_type": "stream",
          "text": [
            "Traceback (most recent call last):\n",
            "  File \"/usr/local/lib/python3.10/dist-packages/IPython/core/interactiveshell.py\", line 3553, in run_code\n",
            "    exec(code_obj, self.user_global_ns, self.user_ns)\n",
            "  File \"<ipython-input-25-5dbe3b72114c>\", line 1, in <cell line: 1>\n",
            "    pd.read_csv(f\"{path}/Angola.csv\")\n",
            "  File \"/usr/local/lib/python3.10/dist-packages/pandas/util/_decorators.py\", line 211, in wrapper\n",
            "    return func(*args, **kwargs)\n",
            "  File \"/usr/local/lib/python3.10/dist-packages/pandas/util/_decorators.py\", line 331, in wrapper\n",
            "    return func(*args, **kwargs)\n",
            "  File \"/usr/local/lib/python3.10/dist-packages/pandas/io/parsers/readers.py\", line 950, in read_csv\n",
            "    return _read(filepath_or_buffer, kwds)\n",
            "  File \"/usr/local/lib/python3.10/dist-packages/pandas/io/parsers/readers.py\", line 605, in _read\n",
            "    parser = TextFileReader(filepath_or_buffer, **kwds)\n",
            "  File \"/usr/local/lib/python3.10/dist-packages/pandas/io/parsers/readers.py\", line 1442, in __init__\n",
            "    self._engine = self._make_engine(f, self.engine)\n",
            "  File \"/usr/local/lib/python3.10/dist-packages/pandas/io/parsers/readers.py\", line 1735, in _make_engine\n",
            "    self.handles = get_handle(\n",
            "  File \"/usr/local/lib/python3.10/dist-packages/pandas/io/common.py\", line 704, in get_handle\n",
            "    if _is_binary_mode(path_or_buf, mode) and \"b\" not in mode:\n",
            "  File \"/usr/local/lib/python3.10/dist-packages/pandas/io/common.py\", line 1163, in _is_binary_mode\n",
            "    return isinstance(handle, _get_binary_io_classes()) or \"b\" in getattr(\n",
            "  File \"/usr/local/lib/python3.10/dist-packages/pandas/io/common.py\", line 1178, in _get_binary_io_classes\n",
            "    zstd = import_optional_dependency(\"zstandard\", errors=\"ignore\")\n",
            "  File \"/usr/local/lib/python3.10/dist-packages/pandas/compat/_optional.py\", line 141, in import_optional_dependency\n",
            "    module = importlib.import_module(name)\n",
            "  File \"/usr/lib/python3.10/importlib/__init__.py\", line 126, in import_module\n",
            "    return _bootstrap._gcd_import(name[level:], package, level)\n",
            "  File \"<frozen importlib._bootstrap>\", line 1050, in _gcd_import\n",
            "  File \"<frozen importlib._bootstrap>\", line 1027, in _find_and_load\n",
            "  File \"<frozen importlib._bootstrap>\", line 1002, in _find_and_load_unlocked\n",
            "  File \"<frozen importlib._bootstrap>\", line 945, in _find_spec\n",
            "  File \"<frozen importlib._bootstrap_external>\", line 1439, in find_spec\n",
            "  File \"<frozen importlib._bootstrap_external>\", line 1408, in _get_spec\n",
            "  File \"<frozen importlib._bootstrap_external>\", line 1366, in _path_importer_cache\n",
            "OSError: [Errno 107] Transport endpoint is not connected\n",
            "\n",
            "During handling of the above exception, another exception occurred:\n",
            "\n",
            "Traceback (most recent call last):\n",
            "  File \"/usr/local/lib/python3.10/dist-packages/IPython/core/interactiveshell.py\", line 2099, in showtraceback\n",
            "    stb = value._render_traceback_()\n",
            "AttributeError: 'OSError' object has no attribute '_render_traceback_'\n",
            "\n",
            "During handling of the above exception, another exception occurred:\n",
            "\n",
            "Traceback (most recent call last):\n",
            "  File \"/usr/local/lib/python3.10/dist-packages/IPython/core/ultratb.py\", line 1101, in get_records\n",
            "    return _fixed_getinnerframes(etb, number_of_lines_of_context, tb_offset)\n",
            "  File \"/usr/local/lib/python3.10/dist-packages/IPython/core/ultratb.py\", line 248, in wrapped\n",
            "    return f(*args, **kwargs)\n",
            "  File \"/usr/local/lib/python3.10/dist-packages/IPython/core/ultratb.py\", line 281, in _fixed_getinnerframes\n",
            "    records = fix_frame_records_filenames(inspect.getinnerframes(etb, context))\n",
            "  File \"/usr/lib/python3.10/inspect.py\", line 1662, in getinnerframes\n",
            "    frameinfo = (tb.tb_frame,) + getframeinfo(tb, context)\n",
            "  File \"/usr/lib/python3.10/inspect.py\", line 1620, in getframeinfo\n",
            "    filename = getsourcefile(frame) or getfile(frame)\n",
            "  File \"/usr/lib/python3.10/inspect.py\", line 829, in getsourcefile\n",
            "    module = getmodule(object, filename)\n",
            "  File \"/usr/lib/python3.10/inspect.py\", line 861, in getmodule\n",
            "    file = getabsfile(object, _filename)\n",
            "  File \"/usr/lib/python3.10/inspect.py\", line 845, in getabsfile\n",
            "    return os.path.normcase(os.path.abspath(_filename))\n",
            "  File \"/usr/lib/python3.10/posixpath.py\", line 384, in abspath\n",
            "    cwd = os.getcwd()\n",
            "OSError: [Errno 107] Transport endpoint is not connected\n",
            "Traceback (most recent call last):\n",
            "  File \"/usr/local/lib/python3.10/dist-packages/IPython/core/interactiveshell.py\", line 3553, in run_code\n",
            "    exec(code_obj, self.user_global_ns, self.user_ns)\n",
            "  File \"<ipython-input-25-5dbe3b72114c>\", line 1, in <cell line: 1>\n",
            "    pd.read_csv(f\"{path}/Angola.csv\")\n",
            "  File \"/usr/local/lib/python3.10/dist-packages/pandas/util/_decorators.py\", line 211, in wrapper\n",
            "    return func(*args, **kwargs)\n",
            "  File \"/usr/local/lib/python3.10/dist-packages/pandas/util/_decorators.py\", line 331, in wrapper\n",
            "    return func(*args, **kwargs)\n",
            "  File \"/usr/local/lib/python3.10/dist-packages/pandas/io/parsers/readers.py\", line 950, in read_csv\n",
            "    return _read(filepath_or_buffer, kwds)\n",
            "  File \"/usr/local/lib/python3.10/dist-packages/pandas/io/parsers/readers.py\", line 605, in _read\n",
            "    parser = TextFileReader(filepath_or_buffer, **kwds)\n",
            "  File \"/usr/local/lib/python3.10/dist-packages/pandas/io/parsers/readers.py\", line 1442, in __init__\n",
            "    self._engine = self._make_engine(f, self.engine)\n",
            "  File \"/usr/local/lib/python3.10/dist-packages/pandas/io/parsers/readers.py\", line 1735, in _make_engine\n",
            "    self.handles = get_handle(\n",
            "  File \"/usr/local/lib/python3.10/dist-packages/pandas/io/common.py\", line 704, in get_handle\n",
            "    if _is_binary_mode(path_or_buf, mode) and \"b\" not in mode:\n",
            "  File \"/usr/local/lib/python3.10/dist-packages/pandas/io/common.py\", line 1163, in _is_binary_mode\n",
            "    return isinstance(handle, _get_binary_io_classes()) or \"b\" in getattr(\n",
            "  File \"/usr/local/lib/python3.10/dist-packages/pandas/io/common.py\", line 1178, in _get_binary_io_classes\n",
            "    zstd = import_optional_dependency(\"zstandard\", errors=\"ignore\")\n",
            "  File \"/usr/local/lib/python3.10/dist-packages/pandas/compat/_optional.py\", line 141, in import_optional_dependency\n",
            "    module = importlib.import_module(name)\n",
            "  File \"/usr/lib/python3.10/importlib/__init__.py\", line 126, in import_module\n",
            "    return _bootstrap._gcd_import(name[level:], package, level)\n",
            "  File \"<frozen importlib._bootstrap>\", line 1050, in _gcd_import\n",
            "  File \"<frozen importlib._bootstrap>\", line 1027, in _find_and_load\n",
            "  File \"<frozen importlib._bootstrap>\", line 1002, in _find_and_load_unlocked\n",
            "  File \"<frozen importlib._bootstrap>\", line 945, in _find_spec\n",
            "  File \"<frozen importlib._bootstrap_external>\", line 1439, in find_spec\n",
            "  File \"<frozen importlib._bootstrap_external>\", line 1408, in _get_spec\n",
            "  File \"<frozen importlib._bootstrap_external>\", line 1366, in _path_importer_cache\n",
            "OSError: [Errno 107] Transport endpoint is not connected\n",
            "\n",
            "During handling of the above exception, another exception occurred:\n",
            "\n",
            "Traceback (most recent call last):\n",
            "  File \"/usr/local/lib/python3.10/dist-packages/IPython/core/interactiveshell.py\", line 2099, in showtraceback\n",
            "    stb = value._render_traceback_()\n",
            "AttributeError: 'OSError' object has no attribute '_render_traceback_'\n",
            "\n",
            "During handling of the above exception, another exception occurred:\n",
            "\n",
            "Traceback (most recent call last):\n",
            "  File \"/usr/local/lib/python3.10/dist-packages/IPython/core/interactiveshell.py\", line 3473, in run_ast_nodes\n",
            "    if (await self.run_code(code, result,  async_=asy)):\n",
            "  File \"/usr/local/lib/python3.10/dist-packages/IPython/core/interactiveshell.py\", line 3575, in run_code\n",
            "    self.showtraceback(running_compiled_code=True)\n",
            "  File \"/usr/local/lib/python3.10/dist-packages/IPython/core/interactiveshell.py\", line 2101, in showtraceback\n",
            "    stb = self.InteractiveTB.structured_traceback(etype,\n",
            "  File \"/usr/local/lib/python3.10/dist-packages/IPython/core/ultratb.py\", line 1367, in structured_traceback\n",
            "    return FormattedTB.structured_traceback(\n",
            "  File \"/usr/local/lib/python3.10/dist-packages/IPython/core/ultratb.py\", line 1267, in structured_traceback\n",
            "    return VerboseTB.structured_traceback(\n",
            "  File \"/usr/local/lib/python3.10/dist-packages/IPython/core/ultratb.py\", line 1124, in structured_traceback\n",
            "    formatted_exception = self.format_exception_as_a_whole(etype, evalue, etb, number_of_lines_of_context,\n",
            "  File \"/usr/local/lib/python3.10/dist-packages/IPython/core/ultratb.py\", line 1082, in format_exception_as_a_whole\n",
            "    last_unique, recursion_repeat = find_recursion(orig_etype, evalue, records)\n",
            "  File \"/usr/local/lib/python3.10/dist-packages/IPython/core/ultratb.py\", line 382, in find_recursion\n",
            "    return len(records), 0\n",
            "TypeError: object of type 'NoneType' has no len()\n",
            "\n",
            "During handling of the above exception, another exception occurred:\n",
            "\n",
            "Traceback (most recent call last):\n",
            "  File \"/usr/local/lib/python3.10/dist-packages/IPython/core/interactiveshell.py\", line 2099, in showtraceback\n",
            "    stb = value._render_traceback_()\n",
            "AttributeError: 'TypeError' object has no attribute '_render_traceback_'\n",
            "\n",
            "During handling of the above exception, another exception occurred:\n",
            "\n",
            "Traceback (most recent call last):\n",
            "  File \"/usr/local/lib/python3.10/dist-packages/IPython/core/ultratb.py\", line 1101, in get_records\n",
            "    return _fixed_getinnerframes(etb, number_of_lines_of_context, tb_offset)\n",
            "  File \"/usr/local/lib/python3.10/dist-packages/IPython/core/ultratb.py\", line 248, in wrapped\n",
            "    return f(*args, **kwargs)\n",
            "  File \"/usr/local/lib/python3.10/dist-packages/IPython/core/ultratb.py\", line 281, in _fixed_getinnerframes\n",
            "    records = fix_frame_records_filenames(inspect.getinnerframes(etb, context))\n",
            "  File \"/usr/lib/python3.10/inspect.py\", line 1662, in getinnerframes\n",
            "    frameinfo = (tb.tb_frame,) + getframeinfo(tb, context)\n",
            "  File \"/usr/lib/python3.10/inspect.py\", line 1620, in getframeinfo\n",
            "    filename = getsourcefile(frame) or getfile(frame)\n",
            "  File \"/usr/lib/python3.10/inspect.py\", line 829, in getsourcefile\n",
            "    module = getmodule(object, filename)\n",
            "  File \"/usr/lib/python3.10/inspect.py\", line 861, in getmodule\n",
            "    file = getabsfile(object, _filename)\n",
            "  File \"/usr/lib/python3.10/inspect.py\", line 845, in getabsfile\n",
            "    return os.path.normcase(os.path.abspath(_filename))\n",
            "  File \"/usr/lib/python3.10/posixpath.py\", line 384, in abspath\n",
            "    cwd = os.getcwd()\n",
            "OSError: [Errno 107] Transport endpoint is not connected\n",
            "Traceback (most recent call last):\n",
            "  File \"/usr/local/lib/python3.10/dist-packages/IPython/core/interactiveshell.py\", line 3553, in run_code\n",
            "    exec(code_obj, self.user_global_ns, self.user_ns)\n",
            "  File \"<ipython-input-25-5dbe3b72114c>\", line 1, in <cell line: 1>\n",
            "    pd.read_csv(f\"{path}/Angola.csv\")\n",
            "  File \"/usr/local/lib/python3.10/dist-packages/pandas/util/_decorators.py\", line 211, in wrapper\n",
            "    return func(*args, **kwargs)\n",
            "  File \"/usr/local/lib/python3.10/dist-packages/pandas/util/_decorators.py\", line 331, in wrapper\n",
            "    return func(*args, **kwargs)\n",
            "  File \"/usr/local/lib/python3.10/dist-packages/pandas/io/parsers/readers.py\", line 950, in read_csv\n",
            "    return _read(filepath_or_buffer, kwds)\n",
            "  File \"/usr/local/lib/python3.10/dist-packages/pandas/io/parsers/readers.py\", line 605, in _read\n",
            "    parser = TextFileReader(filepath_or_buffer, **kwds)\n",
            "  File \"/usr/local/lib/python3.10/dist-packages/pandas/io/parsers/readers.py\", line 1442, in __init__\n",
            "    self._engine = self._make_engine(f, self.engine)\n",
            "  File \"/usr/local/lib/python3.10/dist-packages/pandas/io/parsers/readers.py\", line 1735, in _make_engine\n",
            "    self.handles = get_handle(\n",
            "  File \"/usr/local/lib/python3.10/dist-packages/pandas/io/common.py\", line 704, in get_handle\n",
            "    if _is_binary_mode(path_or_buf, mode) and \"b\" not in mode:\n",
            "  File \"/usr/local/lib/python3.10/dist-packages/pandas/io/common.py\", line 1163, in _is_binary_mode\n",
            "    return isinstance(handle, _get_binary_io_classes()) or \"b\" in getattr(\n",
            "  File \"/usr/local/lib/python3.10/dist-packages/pandas/io/common.py\", line 1178, in _get_binary_io_classes\n",
            "    zstd = import_optional_dependency(\"zstandard\", errors=\"ignore\")\n",
            "  File \"/usr/local/lib/python3.10/dist-packages/pandas/compat/_optional.py\", line 141, in import_optional_dependency\n",
            "    module = importlib.import_module(name)\n",
            "  File \"/usr/lib/python3.10/importlib/__init__.py\", line 126, in import_module\n",
            "    return _bootstrap._gcd_import(name[level:], package, level)\n",
            "  File \"<frozen importlib._bootstrap>\", line 1050, in _gcd_import\n",
            "  File \"<frozen importlib._bootstrap>\", line 1027, in _find_and_load\n",
            "  File \"<frozen importlib._bootstrap>\", line 1002, in _find_and_load_unlocked\n",
            "  File \"<frozen importlib._bootstrap>\", line 945, in _find_spec\n",
            "  File \"<frozen importlib._bootstrap_external>\", line 1439, in find_spec\n",
            "  File \"<frozen importlib._bootstrap_external>\", line 1408, in _get_spec\n",
            "  File \"<frozen importlib._bootstrap_external>\", line 1366, in _path_importer_cache\n",
            "OSError: [Errno 107] Transport endpoint is not connected\n",
            "\n",
            "During handling of the above exception, another exception occurred:\n",
            "\n",
            "Traceback (most recent call last):\n",
            "  File \"/usr/local/lib/python3.10/dist-packages/IPython/core/interactiveshell.py\", line 2099, in showtraceback\n",
            "    stb = value._render_traceback_()\n",
            "AttributeError: 'OSError' object has no attribute '_render_traceback_'\n",
            "\n",
            "During handling of the above exception, another exception occurred:\n",
            "\n",
            "Traceback (most recent call last):\n",
            "  File \"/usr/local/lib/python3.10/dist-packages/IPython/core/interactiveshell.py\", line 3473, in run_ast_nodes\n",
            "    if (await self.run_code(code, result,  async_=asy)):\n",
            "  File \"/usr/local/lib/python3.10/dist-packages/IPython/core/interactiveshell.py\", line 3575, in run_code\n",
            "    self.showtraceback(running_compiled_code=True)\n",
            "  File \"/usr/local/lib/python3.10/dist-packages/IPython/core/interactiveshell.py\", line 2101, in showtraceback\n",
            "    stb = self.InteractiveTB.structured_traceback(etype,\n",
            "  File \"/usr/local/lib/python3.10/dist-packages/IPython/core/ultratb.py\", line 1367, in structured_traceback\n",
            "    return FormattedTB.structured_traceback(\n",
            "  File \"/usr/local/lib/python3.10/dist-packages/IPython/core/ultratb.py\", line 1267, in structured_traceback\n",
            "    return VerboseTB.structured_traceback(\n",
            "  File \"/usr/local/lib/python3.10/dist-packages/IPython/core/ultratb.py\", line 1124, in structured_traceback\n",
            "    formatted_exception = self.format_exception_as_a_whole(etype, evalue, etb, number_of_lines_of_context,\n",
            "  File \"/usr/local/lib/python3.10/dist-packages/IPython/core/ultratb.py\", line 1082, in format_exception_as_a_whole\n",
            "    last_unique, recursion_repeat = find_recursion(orig_etype, evalue, records)\n",
            "  File \"/usr/local/lib/python3.10/dist-packages/IPython/core/ultratb.py\", line 382, in find_recursion\n",
            "    return len(records), 0\n",
            "TypeError: object of type 'NoneType' has no len()\n",
            "\n",
            "During handling of the above exception, another exception occurred:\n",
            "\n",
            "Traceback (most recent call last):\n",
            "  File \"/usr/local/lib/python3.10/dist-packages/IPython/core/interactiveshell.py\", line 2099, in showtraceback\n",
            "    stb = value._render_traceback_()\n",
            "AttributeError: 'TypeError' object has no attribute '_render_traceback_'\n",
            "\n",
            "During handling of the above exception, another exception occurred:\n",
            "\n",
            "Traceback (most recent call last):\n",
            "  File \"/usr/local/lib/python3.10/dist-packages/IPython/core/interactiveshell.py\", line 3030, in _run_cell\n",
            "    return runner(coro)\n",
            "  File \"/usr/local/lib/python3.10/dist-packages/IPython/core/async_helpers.py\", line 78, in _pseudo_sync_runner\n",
            "    coro.send(None)\n",
            "  File \"/usr/local/lib/python3.10/dist-packages/IPython/core/interactiveshell.py\", line 3257, in run_cell_async\n",
            "    has_raised = await self.run_ast_nodes(code_ast.body, cell_name,\n",
            "  File \"/usr/local/lib/python3.10/dist-packages/IPython/core/interactiveshell.py\", line 3492, in run_ast_nodes\n",
            "    self.showtraceback()\n",
            "  File \"/usr/local/lib/python3.10/dist-packages/IPython/core/interactiveshell.py\", line 2101, in showtraceback\n",
            "    stb = self.InteractiveTB.structured_traceback(etype,\n",
            "  File \"/usr/local/lib/python3.10/dist-packages/IPython/core/ultratb.py\", line 1367, in structured_traceback\n",
            "    return FormattedTB.structured_traceback(\n",
            "  File \"/usr/local/lib/python3.10/dist-packages/IPython/core/ultratb.py\", line 1267, in structured_traceback\n",
            "    return VerboseTB.structured_traceback(\n",
            "  File \"/usr/local/lib/python3.10/dist-packages/IPython/core/ultratb.py\", line 1142, in structured_traceback\n",
            "    formatted_exceptions += self.format_exception_as_a_whole(etype, evalue, etb, lines_of_context,\n",
            "  File \"/usr/local/lib/python3.10/dist-packages/IPython/core/ultratb.py\", line 1082, in format_exception_as_a_whole\n",
            "    last_unique, recursion_repeat = find_recursion(orig_etype, evalue, records)\n",
            "  File \"/usr/local/lib/python3.10/dist-packages/IPython/core/ultratb.py\", line 382, in find_recursion\n",
            "    return len(records), 0\n",
            "TypeError: object of type 'NoneType' has no len()\n",
            "\n",
            "During handling of the above exception, another exception occurred:\n",
            "\n",
            "Traceback (most recent call last):\n",
            "  File \"/usr/local/lib/python3.10/dist-packages/IPython/core/interactiveshell.py\", line 2099, in showtraceback\n",
            "    stb = value._render_traceback_()\n",
            "AttributeError: 'TypeError' object has no attribute '_render_traceback_'\n",
            "\n",
            "During handling of the above exception, another exception occurred:\n",
            "\n",
            "Traceback (most recent call last):\n",
            "  File \"/usr/local/lib/python3.10/dist-packages/IPython/core/ultratb.py\", line 1101, in get_records\n",
            "    return _fixed_getinnerframes(etb, number_of_lines_of_context, tb_offset)\n",
            "  File \"/usr/local/lib/python3.10/dist-packages/IPython/core/ultratb.py\", line 248, in wrapped\n",
            "    return f(*args, **kwargs)\n",
            "  File \"/usr/local/lib/python3.10/dist-packages/IPython/core/ultratb.py\", line 281, in _fixed_getinnerframes\n",
            "    records = fix_frame_records_filenames(inspect.getinnerframes(etb, context))\n",
            "  File \"/usr/lib/python3.10/inspect.py\", line 1662, in getinnerframes\n",
            "    frameinfo = (tb.tb_frame,) + getframeinfo(tb, context)\n",
            "  File \"/usr/lib/python3.10/inspect.py\", line 1620, in getframeinfo\n",
            "    filename = getsourcefile(frame) or getfile(frame)\n",
            "  File \"/usr/lib/python3.10/inspect.py\", line 829, in getsourcefile\n",
            "    module = getmodule(object, filename)\n",
            "  File \"/usr/lib/python3.10/inspect.py\", line 861, in getmodule\n",
            "    file = getabsfile(object, _filename)\n",
            "  File \"/usr/lib/python3.10/inspect.py\", line 845, in getabsfile\n",
            "    return os.path.normcase(os.path.abspath(_filename))\n",
            "  File \"/usr/lib/python3.10/posixpath.py\", line 384, in abspath\n",
            "    cwd = os.getcwd()\n",
            "OSError: [Errno 107] Transport endpoint is not connected\n"
          ]
        }
      ],
      "source": [
        "pd.read_csv(f\"{path}/Angola.csv\")"
      ]
    },
    {
      "cell_type": "code",
      "execution_count": null,
      "metadata": {
        "id": "aFDU0ntfihJD"
      },
      "outputs": [],
      "source": []
    }
  ],
  "metadata": {
    "colab": {
      "provenance": [],
      "authorship_tag": "ABX9TyP5HgxwN1YLuiyPG63uKaQG",
      "include_colab_link": true
    },
    "kernelspec": {
      "display_name": "Python 3",
      "name": "python3"
    },
    "language_info": {
      "name": "python"
    }
  },
  "nbformat": 4,
  "nbformat_minor": 0
}